Workbook

Sheet 选品看板
A1: 闲鱼选品评级看板 · 产品编码表全量评估
A2: 数据源：产品编码.xlsx（7品牌 605 SKU）｜测算依据：闲鱼实时在售竞品价格分位、想要热度、竞争格局｜生成日期：2026-10-30
A3: 评估品类数 | C3: 可上架SKU数 | E3: S级爆款品类 | G3: A级铺货品类 | I3: 主推SKU占比
A4: =COUNTA(品类评级!B3:B106) -> 104 | C4: =COUNTA(SKU明细!B3:B607) -> 605 | E4: =COUNTIF(品类评级!C3:C106,"S") -> 1 | G4: =COUNTIF(品类评级!C3:C106,"A") -> 16 | I4: =IFERROR((COUNTIF(SKU明细!C3:C607,"S")+COUNTIF(SKU明细!C3:C607,"A"))/COUNTA(SKU明细!B3:B607),"") -> 0.11570248
A24: 评级 | B24: 品类数 | C24: SKU数 | D24: SKU占比 | F24: Top 12 优先铺货品类
A25: S | B25: =COUNTIF(品类评级!C3:C106,"S") -> 1 | C25: =COUNTIF(SKU明细!C3:C607,"S") -> 23 | D25: =IFERROR(C25/COUNTA(SKU明细!B3:B607),"") -> 0.038016529 | F25: 品类 | G25: 评级 | H25: 评分 | I25: 建议售价 | J25: 区间
A26: A | B26: =COUNTIF(品类评级!C3:C106,"A") -> 16 | C26: =COUNTIF(SKU明细!C3:C607,"A") -> 47 | D26: =IFERROR(C26/COUNTA(SKU明细!B3:B607),"") -> 0.07768595 | F26: 剃须刀刀头 | G26: S | H26: 8.17 | I26: 12 | J26: ¥9–15
A27: B | B27: =COUNTIF(品类评级!C3:C106,"B") -> 64 | C27: =COUNTIF(SKU明细!C3:C607,"B") -> 428 | D27: =IFERROR(C27/COUNTA(SKU明细!B3:B607),"") -> 0.70743802 | F27: 真空封口机 | G27: A | H27: 7.11 | I27: 26 | J27: ¥24–29
A28: C | B28: =COUNTIF(品类评级!C3:C106,"C") -> 22 | C28: =COUNTIF(SKU明细!C3:C607,"C") -> 103 | D28: =IFERROR(C28/COUNTA(SKU明细!B3:B607),"") -> 0.17024793 | F28: 高速吹风机 | G28: A | H28: 6.93 | I28: 55 | J28: ¥42–68
A29: D | B29: =COUNTIF(品类评级!C3:C106,"D") -> 1 | C29: =COUNTIF(SKU明细!C3:C607,"D") -> 4 | D29: =IFERROR(C29/COUNTA(SKU明细!B3:B607),"") -> 0.0066115702 | F29: 宠物修剪器 | G29: A | H29: 6.92 | I29: 18 | J29: ¥16–19
F30: 保暖口罩 | G30: A | H30: 6.87 | I30: 16 | J30: ¥15–16
F31: 手动刮胡刀 | G31: A | H31: 6.82 | I31: 24 | J31: ¥20–29
F32: 机油 | G32: A | H32: 6.8 | I32: 28 | J32: ¥17–40
F33: 迷你清洗杯 | G33: A | H33: 6.8 | I33: 2 | J33: ¥2–3
F34: 小气泡美容仪 | G34: A | H34: 6.79 | I34: 122 | J34: ¥105–139
F35: 防晒口罩 | G35: A | H35: 6.77 | I35: 14 | J35: ¥13–14
F36: 电动修眉刀 | G36: A | H36: 6.69 | I36: 12 | J36: ¥12–13
F37: 超声波清洗机 | G37: A | H37: 6.69 | I37: 50 | J37: ¥40–59

Sheet 品类评级
A1: 品类评级明细（评分 = 需求26% + 利润20% + 竞争16% + 售后14% + 合规10% + 新手9% + 复购5%，再按品牌力与合规红线调整）
A2: 序号 | B2: 品类 | C2: 评级 | D2: 综合评分 | E2: 竞品中位价 | F2: 建议售价 | G2: 建议区间 | H2: 最低可接受价 | I2: 竞品P25 | J2: 竞品P75 | K2: 想要中位 | L2: 在售样本 | M2: 全新占比 | N2: 需求 | O2: 利润 | P2: 竞争 | Q2: 售后 | R2: 合规 | S2: 新手 | T2: 复购 | U2: SKU数 | V2: 推荐理由 | W2: 行动建议
A3: 1 | B3: 剃须刀刀头 | C3: S | D3: 8.17 | E3: 15 | F3: 12 | G3: ¥9–15 | H3: 8 | I3: 11 | J3: 26 | K3: 113 | L3: 30 | M3: 0.6 | N3: 9.1 | O3: 5.5 | P3: 6.5 | Q3: 8 | R3: 10 | S3: 10 | T3: 10 | U3: =COUNTIF(SKU明细!D3:D607,B3) -> 23 | V3: 需求端表现突出：Top30 在售商品的「想要」人数中位数达 113，合计 8497 人次，说明该品类在闲鱼有稳定的自然搜索承接力；价格中等：全新竞品中位价 ¥15，主流带 ¥11–26，薄利走量，需控运损；竞争中等：Top30 中出现 5 个不同品牌，需要在主图和标题上做出差异；售后偏高：属电器/易损品类，需提前说明退换规则，建议保留开箱视频；⚠️ 合规强监管：属强资质敏感品类，资质/标签/宣称任一不合规即触发下架或扣分；耗材属性强：可与主机绑定做「主品+耗材」复购套餐，锁定回头客；新手友好：商品好描述、体积小发货轻、决策快，适合铺量上架 | W3: 全员力推，首批打满库存；标题带「全新未拆封+实拍」，主图放品牌背书
A4: 2 | B4: 真空封口机 | C4: A | D4: 7.11 | E4: 29 | F4: 26 | G4: ¥24–29 | H4: 15 | I4: 25 | J4: 35 | K4: 78 | L4: 30 | M4: 0.8 | N4: 8.5 | O4: 6.8 | P4: 6.2 | Q4: 3 | R4: 10 | S4: 8 | T4: 6 | U4: =COUNTIF(SKU明细!D3:D607,B4) -> 9 | V4: 需求端表现突出：Top30 在售商品的「想要」人数中位数达 78，合计 9156 人次，说明该品类在闲鱼有稳定的自然搜索承接力；价格中等：全新竞品中位价 ¥29，主流带 ¥25–35，薄利走量，需控运损；竞争中等：Top30 中出现 2 个不同品牌，需要在主图和标题上做出差异；售后风险极低：非电器或耗材形态，基本无充电/质保/退货纠纷；⚠️ 合规强监管：属强资质敏感品类，资质/标签/宣称任一不合规即触发下架或扣分；有一定复购：刀头/磨头/袋装等配套件可带动二次成交；该品类样本中未见自有品牌在售，属空白位——无内卷，但也需教育市场成本；新手友好：商品好描述、体积小发货轻、决策快，适合铺量上架 | W4: 重点铺货，建议配 3-5 个颜色SKU组套出图；可做「主推+搭售」组合
A5: 3 | B5: 高速吹风机 | C5: A | D5: 6.93 | E5: 68 | F5: 55 | G5: ¥42–68 | H5: 36 | I5: 42 | J5: 80 | K5: 41 | L5: 30 | M5: 0.77 | N5: 6.6 | O5: 8.5 | P5: 6.6 | Q5: 2 | R5: 9 | S5: 7 | T5: 6 | U5: =COUNTIF(SKU明细!D3:D607,B5) -> 2 | V5: 需求端表现突出：Top30 在售商品的「想要」人数中位数达 41，合计 7295 人次，说明该品类在闲鱼有稳定的自然搜索承接力；单件利润空间可观：全新竞品中位价 ¥68，P25–P75 主流带 ¥42–80，有腾挪定价空间；竞争中等：Top30 中出现 3 个不同品牌，需要在主图和标题上做出差异；售后风险极低：非电器或耗材形态，基本无充电/质保/退货纠纷；⚠️ 合规强监管：属强资质敏感品类，资质/标签/宣称任一不合规即触发下架或扣分；有一定复购：刀头/磨头/袋装等配套件可带动二次成交；该品类样本中未见自有品牌在售，属空白位——无内卷，但也需教育市场成本 | W5: 重点铺货，建议配 3-5 个颜色SKU组套出图；可做「主推+搭售」组合
A6: 4 | B6: 宠物修剪器 | C6: A | D6: 6.92 | E6: 19 | F6: 18 | G6: ¥16–19 | H6: 15 | I6: 17 | J6: 32 | K6: 156 | L6: 30 | M6: 0.77 | N6: 9.7 | O6: 6 | P6: 6.6 | Q6: 2 | R6: 10 | S6: 7 | T6: 5 | U6: =COUNTIF(SKU明细!D3:D607,B6) -> 1 | V6: 需求端表现突出：Top30 在售商品的「想要」人数中位数达 156，合计 3708 人次，说明该品类在闲鱼有稳定的自然搜索承接力；价格中等：全新竞品中位价 ¥19，主流带 ¥17–32，薄利走量，需控运损；竞争中等：Top30 中出现 0 个不同品牌，需要在主图和标题上做出差异；售后风险极低：非电器或耗材形态，基本无充电/质保/退货纠纷；⚠️ 合规强监管：属强资质敏感品类，资质/标签/宣称任一不合规即触发下架或扣分；有一定复购：刀头/磨头/袋装等配套件可带动二次成交；该品类样本中未见自有品牌在售，属空白位——无内卷，但也需教育市场成本 | W6: 重点铺货，建议配 3-5 个颜色SKU组套出图；可做「主推+搭售」组合
A7: 5 | B7: 保暖口罩 | C7: A | D7: 6.87 | E7: 16 | F7: 16 | G7: ¥15–16 | H7: 13 | I7: 15 | J7: 18 | K7: 112.5 | L7: 30 | M7: 0.77 | N7: 9.1 | O7: 5.7 | P7: 6.3 | Q7: 5 | R7: 5 | S7: 9 | T7: 7 | U7: =COUNTIF(SKU明细!D3:D607,B7) -> 3 | V7: 需求端表现突出：Top30 在售商品的「想要」人数中位数达 112，合计 8568 人次，说明该品类在闲鱼有稳定的自然搜索承接力；价格中等：全新竞品中位价 ¥16，主流带 ¥15–18，薄利走量，需控运损；竞争中等：Top30 中出现 1 个不同品牌，需要在主图和标题上做出差异；售后可控：常规小家电，做好成色描述与功能实测视频即可；宣称需克制：文案避免「治疗/根治/祛斑」等医疗功效词，用「清洁/护理/辅助」表述；有一定复购：刀头/磨头/袋装等配套件可带动二次成交；该品类样本中未见自有品牌在售，属空白位——无内卷，但也需教育市场成本；新手友好：商品好描述、体积小发货轻、决策快，适合铺量上架 | W7: 重点铺货，建议配 3-5 个颜色SKU组套出图；可做「主推+搭售」组合
A8: 6 | B8: 配件周边 | C8: D | D8: 6.85 | E8: 37 | F8: 20 | G8: ¥16–23 | H8: 15 | I8: 27 | J8: 56 | K8: 13 | L8: 30 | M8: 0.77 | N8: 4.6 | O8: 6.9 | P8: 5.6 | Q8: 9 | R8: 10 | S8: 9 | T8: 3 | U8: =COUNTIF(SKU明细!D3:D607,B8) -> 4 | V8: 需求极弱：「想要」人数中位数 13，几乎无自然流量承接；价格中等：全新竞品中位价 ¥37，主流带 ¥27–56，薄利走量，需控运损；竞争中等：Top30 中出现 9 个不同品牌，需要在主图和标题上做出差异；售后偏高：属电器/易损品类，需提前说明退换规则，建议保留开箱视频；⚠️ 合规强监管：非卖品配件/包装物，无独立售卖价值，资质/标签/宣称任一不合规即触发下架或扣分；🔥 自有品牌已在此品类跑通：Top30 竞品中有 5 条是康佳/奥克斯/夏新等自有品牌（占 17%），买家已有认知与搜索基础，上架即有流量基础，试错成本最低；新手友好：商品好描述、体积小发货轻、决策快，适合铺量上架 | W8: 不建议投入：合规/售后/需求三重风险，优先出库存或转做搭售赠品
A9: 7 | B9: 手动刮胡刀 | C9: A | D9: 6.82 | E9: 29 | F9: 24 | G9: ¥20–29 | H9: 9 | I9: 9 | J9: 35 | K9: 8 | L9: 30 | M9: 0.67 | N9: 4.7 | O9: 6.8 | P9: 6.4 | Q9: 7 | R9: 10 | S9: 9 | T9: 9 | U9: =COUNTIF(SKU明细!D3:D607,B9) -> 1 | V9: 需求端表现突出：Top30 在售商品的「想要」人数中位数达 8，合计 4279 人次，说明该品类在闲鱼有稳定的自然搜索承接力；价格中等：全新竞品中位价 ¥29，主流带 ¥9–35，薄利走量，需控运损；竞争中等：Top30 中出现 0 个不同品牌，需要在主图和标题上做出差异；售后可控：常规小家电，做好成色描述与功能实测视频即可；⚠️ 合规强监管：属强资质敏感品类，资质/标签/宣称任一不合规即触发下架或扣分；耗材属性强：可与主机绑定做「主品+耗材」复购套餐，锁定回头客；该品类样本中未见自有品牌在售，属空白位——无内卷，但也需教育市场成本；新手友好：商品好描述、体积小发货轻、决策快，适合铺量上架 | W9: 重点铺货，建议配 3-5 个颜色SKU组套出图；可做「主推+搭售」组合
A10: 8 | B10: 机油 | C10: A | D10: 6.8 | E10: 60 | F10: 28 | G10: ¥17–40 | H10: 16 | I10: 25 | J10: 65 | K10: 20 | L10: 30 | M10: 0.6 | N10: 5.3 | O10: 7.4 | P10: 6.7 | Q10: 7 | R10: 10 | S10: 8 | T10: 8 | U10: =COUNTIF(SKU明细!D3:D607,B10) -> 0 | V10: 需求端表现突出：Top30 在售商品的「想要」人数中位数达 20，合计 1221 人次，说明该品类在闲鱼有稳定的自然搜索承接力；单件利润空间可观：全新竞品中位价 ¥60，P25–P75 主流带 ¥25–65，有腾挪定价空间；竞争中等：Top30 中出现 0 个不同品牌，需要在主图和标题上做出差异；售后可控：常规小家电，做好成色描述与功能实测视频即可；⚠️ 合规强监管：属强资质敏感品类，资质/标签/宣称任一不合规即触发下架或扣分；耗材属性强：可与主机绑定做「主品+耗材」复购套餐，锁定回头客；该品类样本中未见自有品牌在售，属空白位——无内卷，但也需教育市场成本；新手友好：商品好描述、体积小发货轻、决策快，适合铺量上架 | W10: 重点铺货，建议配 3-5 个颜色SKU组套出图；可做「主推+搭售」组合
A11: 9 | B11: 迷你清洗杯 | C11: A | D11: 6.8 | E11: 3 | F11: 2 | G11: ¥2–3 | H11: 2 | I11: 2 | J11: 4 | K11: 78 | L11: 30 | M11: 0.33 | N11: 8.5 | O11: 2.8 | P11: 6.3 | Q11: 7 | R11: 10 | S11: 10 | T11: 8 | U11: =COUNTIF(SKU明细!D3:D607,B11) -> 1 | V11: 需求端表现突出：Top30 在售商品的「想要」人数中位数达 78，合计 8912 人次，说明该品类在闲鱼有稳定的自然搜索承接力；客单偏低：全新竞品中位价 ¥3，单件利润薄，必须靠走量或组合装摊薄运费；竞争中等：Top30 中出现 1 个不同品牌，需要在主图和标题上做出差异；售后可控：常规小家电，做好成色描述与功能实测视频即可；⚠️ 合规强监管：属强资质敏感品类，资质/标签/宣称任一不合规即触发下架或扣分；耗材属性强：可与主机绑定做「主品+耗材」复购套餐，锁定回头客；该品类样本中未见自有品牌在售，属空白位——无内卷，但也需教育市场成本；新手友好：商品好描述、体积小发货轻、决策快，适合铺量上架 | W11: 重点铺货，建议配 3-5 个颜色SKU组套出图；可做「主推+搭售」组合
A12: 10 | B12: 小气泡美容仪 | C12: A | D12: 6.79 | E12: 139 | F12: 122 | G12: ¥105–139 | H12: 93 | I12: 105 | J12: 150 | K12: 14 | L12: 30 | M12: 0 | N12: 5.5 | O12: 9.9 | P12: 6.6 | Q12: 4 | R12: 4 | S12: 7 | T12: 5 | U12: =COUNTIF(SKU明细!D3:D607,B12) -> 2 | V12: 需求端表现突出：Top30 在售商品的「想要」人数中位数达 14，合计 736 人次，说明该品类在闲鱼有稳定的自然搜索承接力；单件利润空间可观：全量竞品中位价 ¥139，P25–P75 主流带 ¥105–150，有腾挪定价空间；竞争中等：Top30 中出现 1 个不同品牌，需要在主图和标题上做出差异；售后风险极低：非电器或耗材形态，基本无充电/质保/退货纠纷；宣称需克制：文案避免「治疗/根治/祛斑」等医疗功效词，用「清洁/护理/辅助」表述；有一定复购：刀头/磨头/袋装等配套件可带动二次成交；自有品牌在该品类已有零星在售（2 条，占 7%），说明存在成交但尚未形成压倒性优势，适合抢占头部位置 | W12: 重点铺货，建议配 3-5 个颜色SKU组套出图；可做「主推+搭售」组合
A13: 11 | B13: 防晒口罩 | C13: A | D13: 6.77 | E13: 16 | F13: 14 | G13: ¥13–14 | H13: 8 | I13: 13 | J13: 19 | K13: 104.5 | L13: 30 | M13: 0.87 | N13: 9 | O13: 5.4 | P13: 6.2 | Q13: 5 | R13: 5 | S13: 9 | T13: 7 | U13: =COUNTIF(SKU明细!D3:D607,B13) -> 9 | V13: 需求端表现突出：Top30 在售商品的「想要」人数中位数达 104，合计 11322 人次，说明该品类在闲鱼有稳定的自然搜索承接力；价格中等：全新竞品中位价 ¥16，主流带 ¥13–19，薄利走量，需控运损；竞争中等：Top30 中出现 1 个不同品牌，需要在主图和标题上做出差异；售后可控：常规小家电，做好成色描述与功能实测视频即可；宣称需克制：文案避免「治疗/根治/祛斑」等医疗功效词，用「清洁/护理/辅助」表述；有一定复购：刀头/磨头/袋装等配套件可带动二次成交；该品类样本中未见自有品牌在售，属空白位——无内卷，但也需教育市场成本；新手友好：商品好描述、体积小发货轻、决策快，适合铺量上架 | W13: 重点铺货，建议配 3-5 个颜色SKU组套出图；可做「主推+搭售」组合
A14: 12 | B14: 电动修眉刀 | C14: A | D14: 6.69 | E14: 19 | F14: 12 | G14: ¥12–13 | H14: 10 | I14: 17 | J14: 58 | K14: 31 | L14: 30 | M14: 0.43 | N14: 6.1 | O14: 5.3 | P14: 6.8 | Q14: 3 | R14: 10 | S14: 9 | T14: 5 | U14: =COUNTIF(SKU明细!D3:D607,B14) -> 2 | V14: 需求端表现突出：Top30 在售商品的「想要」人数中位数达 31，合计 578 人次，说明该品类在闲鱼有稳定的自然搜索承接力；价格中等：全新竞品中位价 ¥19，主流带 ¥17–58，薄利走量，需控运损；竞争中等：Top30 中出现 3 个不同品牌，需要在主图和标题上做出差异；售后风险极低：非电器或耗材形态，基本无充电/质保/退货纠纷；⚠️ 合规强监管：属强资质敏感品类，资质/标签/宣称任一不合规即触发下架或扣分；有一定复购：刀头/磨头/袋装等配套件可带动二次成交；🔥 自有品牌已在此品类跑通：Top30 竞品中有 9 条是康佳/奥克斯/夏新等自有品牌（占 30%），买家已有认知与搜索基础，上架即有流量基础，试错成本最低；新手友好：商品好描述、体积小发货轻、决策快，适合铺量上架 | W14: 重点铺货，建议配 3-5 个颜色SKU组套出图；可做「主推+搭售」组合
A15: 13 | B15: 超声波清洗机 | C15: A | D15: 6.69 | E15: 59 | F15: 50 | G15: ¥40–59 | H15: 18 | I15: 41 | J15: 90 | K15: 12 | L15: 30 | M15: 0.4 | N15: 4.5 | O15: 8.2 | P15: 6.8 | Q15: 4 | R15: 8 | S15: 8 | T15: 7 | U15: =COUNTIF(SKU明细!D3:D607,B15) -> 1 | V15: 需求端表现突出：Top30 在售商品的「想要」人数中位数达 12，合计 8476 人次，说明该品类在闲鱼有稳定的自然搜索承接力；单件利润空间可观：全新竞品中位价 ¥59，P25–P75 主流带 ¥41–90，有腾挪定价空间；竞争中等：Top30 中出现 4 个不同品牌，需要在主图和标题上做出差异；售后风险极低：非电器或耗材形态，基本无充电/质保/退货纠纷；⚠️ 合规强监管：属强资质敏感品类，资质/标签/宣称任一不合规即触发下架或扣分；有一定复购：刀头/磨头/袋装等配套件可带动二次成交；新手友好：商品好描述、体积小发货轻、决策快，适合铺量上架 | W15: 重点铺货，建议配 3-5 个颜色SKU组套出图；可做「主推+搭售」组合
A16: 14 | B16: 马桶卫士 | C16: A | D16: 6.68 | E16: 13 | F16: 12 | G16: ¥12–13 | H16: 7 | I16: 9 | J16: 17 | K16: 50 | L16: 30 | M16: 0.4 | N16: 7.7 | O16: 5.3 | P16: 6.4 | Q16: 6 | R16: 8 | S16: 9 | T16: 8 | U16: =COUNTIF(SKU明细!D3:D607,B16) -> 3 | V16: 需求端表现突出：Top30 在售商品的「想要」人数中位数达 50，合计 2258 人次，说明该品类在闲鱼有稳定的自然搜索承接力；价格中等：全新竞品中位价 ¥13，主流带 ¥9–17，薄利走量，需控运损；竞争中等：Top30 中出现 0 个不同品牌，需要在主图和标题上做出差异；售后可控：常规小家电，做好成色描述与功能实测视频即可；⚠️ 合规强监管：属强资质敏感品类，资质/标签/宣称任一不合规即触发下架或扣分；耗材属性强：可与主机绑定做「主品+耗材」复购套餐，锁定回头客；该品类样本中未见自有品牌在售，属空白位——无内卷，但也需教育市场成本；新手友好：商品好描述、体积小发货轻、决策快，适合铺量上架 | W16: 重点铺货，建议配 3-5 个颜色SKU组套出图；可做「主推+搭售」组合
A17: 15 | B17: 起泡网 | C17: A | D17: 6.66 | E17: 9 | F17: 8 | G17: ¥7–9 | H17: 6 | I17: 4 | J17: 9 | K17: 20 | L17: 30 | M17: 0.47 | N17: 6.1 | O17: 4.6 | P17: 6.5 | Q17: 8 | R17: 10 | S17: 10 | T17: 9 | U17: =COUNTIF(SKU明细!D3:D607,B17) -> 1 | V17: 需求端表现突出：Top30 在售商品的「想要」人数中位数达 20，合计 960 人次，说明该品类在闲鱼有稳定的自然搜索承接力；客单偏低：全新竞品中位价 ¥9，单件利润薄，必须靠走量或组合装摊薄运费；竞争中等：Top30 中出现 0 个不同品牌，需要在主图和标题上做出差异；售后偏高：属电器/易损品类，需提前说明退换规则，建议保留开箱视频；⚠️ 合规强监管：属强资质敏感品类，资质/标签/宣称任一不合规即触发下架或扣分；耗材属性强：可与主机绑定做「主品+耗材」复购套餐，锁定回头客；该品类样本中未见自有品牌在售，属空白位——无内卷，但也需教育市场成本；新手友好：商品好描述、体积小发货轻、决策快，适合铺量上架 | W17: 重点铺货，建议配 3-5 个颜色SKU组套出图；可做「主推+搭售」组合
A18: 16 | B18: 挂腰风扇 | C18: A | D18: 6.65 | E18: 49 | F18: 44 | G18: ¥38–49 | H18: 36 | I18: 38 | J18: 65 | K18: 16 | L18: 30 | M18: 0.47 | N18: 5.8 | O18: 7.8 | P18: 6.4 | Q18: 4 | R18: 10 | S18: 8 | T18: 3 | U18: =COUNTIF(SKU明细!D3:D607,B18) -> 3 | V18: 需求端表现突出：Top30 在售商品的「想要」人数中位数达 16，合计 2412 人次，说明该品类在闲鱼有稳定的自然搜索承接力；单件利润空间可观：全新竞品中位价 ¥49，P25–P75 主流带 ¥38–65，有腾挪定价空间；竞争中等：Top30 中出现 1 个不同品牌，需要在主图和标题上做出差异；售后风险极低：非电器或耗材形态，基本无充电/质保/退货纠纷；⚠️ 合规强监管：属强资质敏感品类，资质/标签/宣称任一不合规即触发下架或扣分；自有品牌在该品类已有零星在售（2 条，占 7%），说明存在成交但尚未形成压倒性优势，适合抢占头部位置；新手友好：商品好描述、体积小发货轻、决策快，适合铺量上架 | W18: 重点铺货，建议配 3-5 个颜色SKU组套出图；可做「主推+搭售」组合
A19: 17 | B19: 循环扇 | C19: A | D19: 6.63 | E19: 24 | F19: 22 | G19: ¥21–24 | H19: 18 | I19: 21 | J19: 25 | K19: 76.5 | L19: 30 | M19: 0.87 | N19: 8.4 | O19: 6.4 | P19: 6.4 | Q19: 2 | R19: 9 | S19: 7 | T19: 4 | U19: =COUNTIF(SKU明细!D3:D607,B19) -> 2 | V19: 需求端表现突出：Top30 在售商品的「想要」人数中位数达 76，合计 24235 人次，说明该品类在闲鱼有稳定的自然搜索承接力；价格中等：全新竞品中位价 ¥24，主流带 ¥21–25，薄利走量，需控运损；竞争中等：Top30 中出现 1 个不同品牌，需要在主图和标题上做出差异；售后风险极低：非电器或耗材形态，基本无充电/质保/退货纠纷；⚠️ 合规强监管：属强资质敏感品类，资质/标签/宣称任一不合规即触发下架或扣分；该品类样本中未见自有品牌在售，属空白位——无内卷，但也需教育市场成本 | W19: 重点铺货，建议配 3-5 个颜色SKU组套出图；可做「主推+搭售」组合
A20: 18 | B20: 自动卷发器 | C20: A | D20: 6.63 | E20: 30 | F20: 25 | G20: ¥20–30 | H20: 18 | I20: 23 | J20: 35 | K20: 59 | L20: 30 | M20: 0.57 | N20: 7.2 | O20: 6.9 | P20: 6.9 | Q20: 1 | R20: 9 | S20: 7 | T20: 5 | U20: =COUNTIF(SKU明细!D3:D607,B20) -> 7 | V20: 需求端表现突出：Top30 在售商品的「想要」人数中位数达 59，合计 4533 人次，说明该品类在闲鱼有稳定的自然搜索承接力；价格中等：全新竞品中位价 ¥30，主流带 ¥23–35，薄利走量，需控运损；竞争中等：Top30 中出现 2 个不同品牌，需要在主图和标题上做出差异；售后风险极低：非电器或耗材形态，基本无充电/质保/退货纠纷；⚠️ 合规强监管：属强资质敏感品类，资质/标签/宣称任一不合规即触发下架或扣分；有一定复购：刀头/磨头/袋装等配套件可带动二次成交；自有品牌在该品类已有零星在售（2 条，占 7%），说明存在成交但尚未形成压倒性优势，适合抢占头部位置 | W20: 重点铺货，建议配 3-5 个颜色SKU组套出图；可做「主推+搭售」组合
A21: 19 | B21: 破壁料理机 | C21: B | D21: 6.6 | E21: 59 | F21: 38 | G21: ¥38–39 | H21: 36 | I21: 44 | J21: 69 | K21: 14 | L21: 30 | M21: 0.33 | N21: 5.5 | O21: 8.1 | P21: 6.6 | Q21: 1 | R21: 9 | S21: 5 | T21: 5 | U21: =COUNTIF(SKU明细!D3:D607,B21) -> 2 | V21: 需求中等：「想要」人数中位数 14、有想要标签的在售占比 16/30，属于有搜索但竞争平缓的常规位；单件利润空间可观：全新竞品中位价 ¥59，P25–P75 主流带 ¥44–69，有腾挪定价空间；竞争中等：Top30 中出现 6 个不同品牌，需要在主图和标题上做出差异；售后风险极低：非电器或耗材形态，基本无充电/质保/退货纠纷；⚠️ 合规强监管：属强资质敏感品类，资质/标签/宣称任一不合规即触发下架或扣分；有一定复购：刀头/磨头/袋装等配套件可带动二次成交；🔥 自有品牌已在此品类跑通：Top30 竞品中有 5 条是康佳/奥克斯/夏新等自有品牌（占 17%），买家已有认知与搜索基础，上架即有流量基础，试错成本最低；新手门槛偏高：需讲清参数/尺寸/安装或操作说明，图文投入要足 | W21: 常规备选，放在长尾分类；用低价冲量，不单独投流
A22: 20 | B22: 除螨皂 | C22: B | D22: 6.59 | E22: 15 | F22: 8 | G22: ¥6–11 | H22: 6 | I22: 9 | J22: 24 | K22: 92.5 | L22: 30 | M22: 0.47 | N22: 8.8 | O22: 5.5 | P22: 6.6 | Q22: 5 | R22: 2 | S22: 9 | T22: 9 | U22: =COUNTIF(SKU明细!D3:D607,B22) -> 1 | V22: 需求中等：「想要」人数中位数 92、有想要标签的在售占比 16/30，属于有搜索但竞争平缓的常规位；价格中等：全新竞品中位价 ¥15，主流带 ¥9–24，薄利走量，需控运损；竞争中等：Top30 中出现 1 个不同品牌，需要在主图和标题上做出差异；售后可控：常规小家电，做好成色描述与功能实测视频即可；无资质门槛：上架无特殊资质要求，标题可自由发挥；耗材属性强：可与主机绑定做「主品+耗材」复购套餐，锁定回头客；该品类样本中未见自有品牌在售，属空白位——无内卷，但也需教育市场成本；新手友好：商品好描述、体积小发货轻、决策快，适合铺量上架 | W22: 常规备选，放在长尾分类；用低价冲量，不单独投流
A23: 21 | B23: 修足器磨头 | C23: B | D23: 6.54 | E23: 30 | F23: 14 | G23: ¥10–17 | H23: 10 | I23: 18 | J23: 43 | K23: 1 | L23: 30 | M23: 0.73 | N23: 1.2 | O23: 6.8 | P23: 6.8 | Q23: 8 | R23: 10 | S23: 10 | T23: 10 | U23: =COUNTIF(SKU明细!D3:D607,B23) -> 6 | V23: 需求中等：「想要」人数中位数 1、有想要标签的在售占比 10/30，属于有搜索但竞争平缓的常规位；价格中等：全新竞品中位价 ¥30，主流带 ¥18–43，薄利走量，需控运损；竞争中等：Top30 中出现 4 个不同品牌，需要在主图和标题上做出差异；售后偏高：属电器/易损品类，需提前说明退换规则，建议保留开箱视频；⚠️ 合规强监管：属强资质敏感品类，资质/标签/宣称任一不合规即触发下架或扣分；耗材属性强：可与主机绑定做「主品+耗材」复购套餐，锁定回头客；🔥 自有品牌已在此品类跑通：Top30 竞品中有 9 条是康佳/奥克斯/夏新等自有品牌（占 30%），买家已有认知与搜索基础，上架即有流量基础，试错成本最低；新手友好：商品好描述、体积小发货轻、决策快，适合铺量上架 | W23: 常规备选，放在长尾分类；用低价冲量，不单独投流
A24: 22 | B24: 车载吸尘器 | C24: B | D24: 6.5 | E24: 39 | F24: 26 | G24: ¥24–29 | H24: 23 | I24: 32 | J24: 48 | K24: 18.5 | L24: 30 | M24: 0.8 | N24: 6 | O24: 7.4 | P24: 6.5 | Q24: 2 | R24: 9 | S24: 7 | T24: 5 | U24: =COUNTIF(SKU明细!D3:D607,B24) -> 14 | V24: 需求中等：「想要」人数中位数 18、有想要标签的在售占比 18/30，属于有搜索但竞争平缓的常规位；单件利润空间可观：全新竞品中位价 ¥39，P25–P75 主流带 ¥32–48，有腾挪定价空间；竞争中等：Top30 中出现 4 个不同品牌，需要在主图和标题上做出差异；售后风险极低：非电器或耗材形态，基本无充电/质保/退货纠纷；⚠️ 合规强监管：属强资质敏感品类，资质/标签/宣称任一不合规即触发下架或扣分；有一定复购：刀头/磨头/袋装等配套件可带动二次成交 | W24: 常规备选，放在长尾分类；用低价冲量，不单独投流
A25: 23 | B25: 采耳耳勺可视 | C25: B | D25: 6.45 | E25: 23 | F25: 15 | G25: ¥15–15 | H25: 14 | I25: 15 | J25: 69 | K25: 53 | L25: 30 | M25: 0.73 | N25: 7 | O25: 6.3 | P25: 6.7 | Q25: 3 | R25: 10 | S25: 8 | T25: 3 | U25: =COUNTIF(SKU明细!D3:D607,B25) -> 2 | V25: 需求中等：「想要」人数中位数 53、有想要标签的在售占比 13/30，属于有搜索但竞争平缓的常规位；价格中等：全新竞品中位价 ¥23，主流带 ¥15–69，薄利走量，需控运损；竞争中等：Top30 中出现 1 个不同品牌，需要在主图和标题上做出差异；售后风险极低：非电器或耗材形态，基本无充电/质保/退货纠纷；⚠️ 合规强监管：属强资质敏感品类，资质/标签/宣称任一不合规即触发下架或扣分；该品类样本中未见自有品牌在售，属空白位——无内卷，但也需教育市场成本；新手友好：商品好描述、体积小发货轻、决策快，适合铺量上架 | W25: 常规备选，放在长尾分类；用低价冲量，不单独投流
A26: 24 | B26: 电动磨甲器 | C26: B | D26: 6.42 | E26: 23 | F26: 14 | G26: ¥13–16 | H26: 12 | I26: 15 | J26: 27 | K26: 102 | L26: 60 | M26: 0.7 | N26: 8.9 | O26: 6.3 | P26: 3.6 | Q26: 2 | R26: 10 | S26: 8 | T26: 5 | U26: =COUNTIF(SKU明细!D3:D607,B26) -> 2 | V26: 需求中等：「想要」人数中位数 102、有想要标签的在售占比 19/30，属于有搜索但竞争平缓的常规位；价格中等：全新竞品中位价 ¥23，主流带 ¥15–27，薄利走量，需控运损；竞争激烈：Top30 里已挤进 0 个品牌，头部品牌已形成价格锚定，正面硬拼不划算；售后风险极低：非电器或耗材形态，基本无充电/质保/退货纠纷；⚠️ 合规强监管：属强资质敏感品类，资质/标签/宣称任一不合规即触发下架或扣分；有一定复购：刀头/磨头/袋装等配套件可带动二次成交；该品类样本中未见自有品牌在售，属空白位——无内卷，但也需教育市场成本；新手友好：商品好描述、体积小发货轻、决策快，适合铺量上架 | W26: 常规备选，放在长尾分类；用低价冲量，不单独投流
A27: 25 | B27: 肩颈按摩器 | C27: B | D27: 6.42 | E27: 35 | F27: 22 | G27: ¥17–28 | H27: 16 | I27: 28 | J27: 51 | K27: 18 | L27: 30 | M27: 0.53 | N27: 5.2 | O27: 7.2 | P27: 6.8 | Q27: 3 | R27: 7 | S27: 7 | T27: 4 | U27: =COUNTIF(SKU明细!D3:D607,B27) -> 10 | V27: 需求中等：「想要」人数中位数 18、有想要标签的在售占比 11/30，属于有搜索但竞争平缓的常规位；单件利润空间可观：全新竞品中位价 ¥35，P25–P75 主流带 ¥28–51，有腾挪定价空间；竞争中等：Top30 中出现 2 个不同品牌，需要在主图和标题上做出差异；售后风险极低：非电器或耗材形态，基本无充电/质保/退货纠纷；⚠️ 合规强监管：属强资质敏感品类，资质/标签/宣称任一不合规即触发下架或扣分；🔥 自有品牌已在此品类跑通：Top30 竞品中有 17 条是康佳/奥克斯/夏新等自有品牌（占 57%），买家已有认知与搜索基础，上架即有流量基础，试错成本最低 | W27: 常规备选，放在长尾分类；用低价冲量，不单独投流
A28: 26 | B28: 烘鞋器 | C28: B | D28: 6.41 | E28: 19 | F28: 14 | G28: ¥11–16 | H28: 10 | I28: 16 | J28: 28 | K28: 26 | L28: 30 | M28: 0.8 | N28: 6.6 | O28: 6 | P28: 6.6 | Q28: 2 | R28: 10 | S28: 8 | T28: 4 | U28: =COUNTIF(SKU明细!D3:D607,B28) -> 2 | V28: 需求中等：「想要」人数中位数 26、有想要标签的在售占比 15/30，属于有搜索但竞争平缓的常规位；价格中等：全新竞品中位价 ¥19，主流带 ¥16–28，薄利走量，需控运损；竞争中等：Top30 中出现 4 个不同品牌，需要在主图和标题上做出差异；售后风险极低：非电器或耗材形态，基本无充电/质保/退货纠纷；⚠️ 合规强监管：属强资质敏感品类，资质/标签/宣称任一不合规即触发下架或扣分；自有品牌在该品类已有零星在售（2 条，占 7%），说明存在成交但尚未形成压倒性优势，适合抢占头部位置；新手友好：商品好描述、体积小发货轻、决策快，适合铺量上架 | W28: 常规备选，放在长尾分类；用低价冲量，不单独投流
A29: 27 | B29: 咖啡豆研磨机 | C29: B | D29: 6.37 | E29: 39 | F29: 18 | G29: ¥14–23 | H29: 13 | I29: 20 | J29: 60 | K29: 16.5 | L29: 30 | M29: 0.73 | N29: 5 | O29: 7.2 | P29: 6.6 | Q29: 3 | R29: 10 | S29: 8 | T29: 6 | U29: =COUNTIF(SKU明细!D3:D607,B29) -> 1 | V29: 需求中等：「想要」人数中位数 16、有想要标签的在售占比 14/30，属于有搜索但竞争平缓的常规位；单件利润空间可观：全新竞品中位价 ¥39，P25–P75 主流带 ¥20–60，有腾挪定价空间；竞争中等：Top30 中出现 4 个不同品牌，需要在主图和标题上做出差异；售后风险极低：非电器或耗材形态，基本无充电/质保/退货纠纷；⚠️ 合规强监管：属强资质敏感品类，资质/标签/宣称任一不合规即触发下架或扣分；有一定复购：刀头/磨头/袋装等配套件可带动二次成交；该品类样本中未见自有品牌在售，属空白位——无内卷，但也需教育市场成本；新手友好：商品好描述、体积小发货轻、决策快，适合铺量上架 | W29: 常规备选，放在长尾分类；用低价冲量，不单独投流
A30: 28 | B30: 直发器 | C30: B | D30: 6.37 | E30: 35 | F30: 17 | G30: ¥15–19 | H30: 14 | I30: 19 | J30: 49 | K30: 4 | L30: 30 | M30: 0.63 | N30: 3.6 | O30: 7.2 | P30: 6.6 | Q30: 2 | R30: 9 | S30: 8 | T30: 6 | U30: =COUNTIF(SKU明细!D3:D607,B30) -> 8 | V30: 需求中等：「想要」人数中位数 4、有想要标签的在售占比 15/30，属于有搜索但竞争平缓的常规位；单件利润空间可观：全新竞品中位价 ¥35，P25–P75 主流带 ¥19–49，有腾挪定价空间；竞争中等：Top30 中出现 4 个不同品牌，需要在主图和标题上做出差异；售后风险极低：非电器或耗材形态，基本无充电/质保/退货纠纷；⚠️ 合规强监管：属强资质敏感品类，资质/标签/宣称任一不合规即触发下架或扣分；有一定复购：刀头/磨头/袋装等配套件可带动二次成交；🔥 自有品牌已在此品类跑通：Top30 竞品中有 5 条是康佳/奥克斯/夏新等自有品牌（占 17%），买家已有认知与搜索基础，上架即有流量基础，试错成本最低；新手友好：商品好描述、体积小发货轻、决策快，适合铺量上架 | W30: 常规备选，放在长尾分类；用低价冲量，不单独投流
A31: 29 | B31: 美容仪 | C31: B | D31: 6.36 | E31: 346 | F31: 289 | G31: ¥280–298 | H31: 266 | I31: 280 | J31: 426 | K31: 26.5 | L31: 30 | M31: 0.67 | N31: 5.8 | O31: 10 | P31: 7 | Q31: 4 | R31: 2 | S31: 6 | T31: 4 | U31: =COUNTIF(SKU明细!D3:D607,B31) -> 7 | V31: 需求中等：「想要」人数中位数 26、有想要标签的在售占比 6/30，属于有搜索但竞争平缓的常规位；单件利润空间可观：全新竞品中位价 ¥346，P25–P75 主流带 ¥280–426，有腾挪定价空间；竞争温和：在售 Top30 覆盖 1 个品牌，格局分散，新链接有出头机会；售后风险极低：非电器或耗材形态，基本无充电/质保/退货纠纷；无资质门槛：上架无特殊资质要求，标题可自由发挥；该品类样本中未见自有品牌在售，属空白位——无内卷，但也需教育市场成本 | W31: 常规备选，放在长尾分类；用低价冲量，不单独投流
A32: 30 | B32: 吹风机 | C32: B | D32: 6.34 | E32: 43 | F32: 26 | G32: ¥15–37 | H32: 14 | I32: 35 | J32: 68 | K32: 48 | L32: 60 | M32: 0.68 | N32: 7.6 | O32: 7.5 | P32: 3.2 | Q32: 2 | R32: 9 | S32: 7 | T32: 6 | U32: =COUNTIF(SKU明细!D3:D607,B32) -> 3 | V32: 需求中等：「想要」人数中位数 48、有想要标签的在售占比 31/30，属于有搜索但竞争平缓的常规位；单件利润空间可观：全新竞品中位价 ¥43，P25–P75 主流带 ¥35–68，有腾挪定价空间；竞争激烈：Top30 里已挤进 6 个品牌，头部品牌已形成价格锚定，正面硬拼不划算；售后风险极低：非电器或耗材形态，基本无充电/质保/退货纠纷；⚠️ 合规强监管：属强资质敏感品类，资质/标签/宣称任一不合规即触发下架或扣分；有一定复购：刀头/磨头/袋装等配套件可带动二次成交；该品类样本中未见自有品牌在售，属空白位——无内卷，但也需教育市场成本 | W32: 常规备选，放在长尾分类；用低价冲量，不单独投流
A33: 31 | B33: 冲牙器 | C33: B | D33: 6.31 | E33: 41 | F33: 20 | G33: ¥20–20 | H33: 19 | I33: 25 | J33: 42 | K33: 3.5 | L33: 30 | M33: 0.47 | N33: 2.6 | O33: 7 | P33: 6.8 | Q33: 3 | R33: 10 | S33: 7 | T33: 7 | U33: =COUNTIF(SKU明细!D3:D607,B33) -> 9 | V33: 需求中等：「想要」人数中位数 4、有想要标签的在售占比 10/30，属于有搜索但竞争平缓的常规位；单件利润空间可观：全新竞品中位价 ¥41，P25–P75 主流带 ¥25–42，有腾挪定价空间；竞争中等：Top30 中出现 3 个不同品牌，需要在主图和标题上做出差异；售后风险极低：非电器或耗材形态，基本无充电/质保/退货纠纷；⚠️ 合规强监管：属强资质敏感品类，资质/标签/宣称任一不合规即触发下架或扣分；有一定复购：刀头/磨头/袋装等配套件可带动二次成交；🔥 自有品牌已在此品类跑通：Top30 竞品中有 12 条是康佳/奥克斯/夏新等自有品牌（占 40%），买家已有认知与搜索基础，上架即有流量基础，试错成本最低 | W33: 常规备选，放在长尾分类；用低价冲量，不单独投流
A34: 32 | B34: 多功能研磨机 | C34: B | D34: 6.31 | E34: 25 | F34: 19 | G34: ¥19–19 | H34: 18 | I34: 19 | J34: 27 | K34: 18 | L34: 30 | M34: 0.77 | N34: 6 | O34: 6.5 | P34: 6.4 | Q34: 3 | R34: 10 | S34: 8 | T34: 6 | U34: =COUNTIF(SKU明细!D3:D607,B34) -> 3 | V34: 需求中等：「想要」人数中位数 18、有想要标签的在售占比 20/30，属于有搜索但竞争平缓的常规位；价格中等：全新竞品中位价 ¥25，主流带 ¥19–27，薄利走量，需控运损；竞争中等：Top30 中出现 0 个不同品牌，需要在主图和标题上做出差异；售后风险极低：非电器或耗材形态，基本无充电/质保/退货纠纷；⚠️ 合规强监管：属强资质敏感品类，资质/标签/宣称任一不合规即触发下架或扣分；有一定复购：刀头/磨头/袋装等配套件可带动二次成交；该品类样本中未见自有品牌在售，属空白位——无内卷，但也需教育市场成本；新手友好：商品好描述、体积小发货轻、决策快，适合铺量上架 | W34: 常规备选，放在长尾分类；用低价冲量，不单独投流
A35: 33 | B35: 洗手液 | C35: B | D35: 6.31 | E35: 7 | F35: 4 | G35: ¥3–5 | H35: 3 | I35: 6 | J35: 13 | K35: 113.5 | L35: 30 | M35: 0.6 | N35: 9.1 | O35: 4.2 | P35: 6.6 | Q35: 5 | R35: 1 | S35: 9 | T35: 9 | U35: =COUNTIF(SKU明细!D3:D607,B35) -> 0 | V35: 需求中等：「想要」人数中位数 114、有想要标签的在售占比 16/30，属于有搜索但竞争平缓的常规位；客单偏低：全新竞品中位价 ¥7，单件利润薄，必须靠走量或组合装摊薄运费；竞争中等：Top30 中出现 0 个不同品牌，需要在主图和标题上做出差异；售后可控：常规小家电，做好成色描述与功能实测视频即可；无资质门槛：上架无特殊资质要求，标题可自由发挥；耗材属性强：可与主机绑定做「主品+耗材」复购套餐，锁定回头客；该品类样本中未见自有品牌在售，属空白位——无内卷，但也需教育市场成本；新手友好：商品好描述、体积小发货轻、决策快，适合铺量上架 | W35: 常规备选，放在长尾分类；用低价冲量，不单独投流
A36: 34 | B36: 电动磨脚器 | C36: B | D36: 6.31 | E36: 29 | F36: 18 | G36: ¥12–24 | H36: 11 | I36: 19 | J36: 36 | K36: 9.5 | L36: 30 | M36: 0.83 | N36: 4.1 | O36: 6.8 | P36: 6.6 | Q36: 2 | R36: 10 | S36: 8 | T36: 4 | U36: =COUNTIF(SKU明细!D3:D607,B36) -> 25 | V36: 需求中等：「想要」人数中位数 10、有想要标签的在售占比 14/30，属于有搜索但竞争平缓的常规位；价格中等：全新竞品中位价 ¥29，主流带 ¥19–36，薄利走量，需控运损；竞争中等：Top30 中出现 3 个不同品牌，需要在主图和标题上做出差异；售后风险极低：非电器或耗材形态，基本无充电/质保/退货纠纷；⚠️ 合规强监管：属强资质敏感品类，资质/标签/宣称任一不合规即触发下架或扣分；🔥 自有品牌已在此品类跑通：Top30 竞品中有 9 条是康佳/奥克斯/夏新等自有品牌（占 30%），买家已有认知与搜索基础，上架即有流量基础，试错成本最低；新手友好：商品好描述、体积小发货轻、决策快，适合铺量上架 | W36: 常规备选，放在长尾分类；用低价冲量，不单独投流
A37: 35 | B37: 鼻毛修剪器刀头 | C37: B | D37: 6.25 | E37: 15 | F37: 4 | G37: ¥4–5 | H37: 4 | I37: 6 | J37: 18 | K37: 5 | L37: 30 | M37: 0.43 | N37: 3.9 | O37: 4.6 | P37: 6.4 | Q37: 8 | R37: 10 | S37: 10 | T37: 10 | U37: =COUNTIF(SKU明细!D3:D607,B37) -> 0 | V37: 需求中等：「想要」人数中位数 5、有想要标签的在售占比 19/30，属于有搜索但竞争平缓的常规位；客单偏低：全新竞品中位价 ¥15，单件利润薄，必须靠走量或组合装摊薄运费；竞争中等：Top30 中出现 5 个不同品牌，需要在主图和标题上做出差异；售后偏高：属电器/易损品类，需提前说明退换规则，建议保留开箱视频；⚠️ 合规强监管：属强资质敏感品类，资质/标签/宣称任一不合规即触发下架或扣分；耗材属性强：可与主机绑定做「主品+耗材」复购套餐，锁定回头客；该品类样本中未见自有品牌在售，属空白位——无内卷，但也需教育市场成本；新手友好：商品好描述、体积小发货轻、决策快，适合铺量上架 | W37: 常规备选，放在长尾分类；用低价冲量，不单独投流
A38: 36 | B38: 粘毛器 | C38: B | D38: 6.22 | E38: 6 | F38: 4 | G38: ¥3–4 | H38: 3 | I38: 3 | J38: 9 | K38: 10.5 | L38: 30 | M38: 0.8 | N38: 5.1 | O38: 3.9 | P38: 6.5 | Q38: 7 | R38: 10 | S38: 10 | T38: 9 | U38: =COUNTIF(SKU明细!D3:D607,B38) -> 0 | V38: 需求中等：「想要」人数中位数 10、有想要标签的在售占比 18/30，属于有搜索但竞争平缓的常规位；客单偏低：全新竞品中位价 ¥6，单件利润薄，必须靠走量或组合装摊薄运费；竞争中等：Top30 中出现 1 个不同品牌，需要在主图和标题上做出差异；售后可控：常规小家电，做好成色描述与功能实测视频即可；⚠️ 合规强监管：属强资质敏感品类，资质/标签/宣称任一不合规即触发下架或扣分；耗材属性强：可与主机绑定做「主品+耗材」复购套餐，锁定回头客；该品类样本中未见自有品牌在售，属空白位——无内卷，但也需教育市场成本；新手友好：商品好描述、体积小发货轻、决策快，适合铺量上架 | W38: 常规备选，放在长尾分类；用低价冲量，不单独投流
A39: 37 | B39: 呼吸哑铃 | C39: B | D39: 6.21 | E39: 80 | F39: 54 | G39: ¥48–59 | H39: 46 | I39: 59 | J39: 108 | K39: 2 | L39: 30 | M39: 0.77 | N39: 1.9 | O39: 8.8 | P39: 6.9 | Q39: 7 | R39: 10 | S39: 9 | T39: 6 | U39: =COUNTIF(SKU明细!D3:D607,B39) -> 1 | V39: 需求中等：「想要」人数中位数 2、有想要标签的在售占比 7/30，属于有搜索但竞争平缓的常规位；单件利润空间可观：全新竞品中位价 ¥80，P25–P75 主流带 ¥59–108，有腾挪定价空间；竞争中等：Top30 中出现 0 个不同品牌，需要在主图和标题上做出差异；售后可控：常规小家电，做好成色描述与功能实测视频即可；⚠️ 合规强监管：属强资质敏感品类，资质/标签/宣称任一不合规即触发下架或扣分；有一定复购：刀头/磨头/袋装等配套件可带动二次成交；该品类样本中未见自有品牌在售，属空白位——无内卷，但也需教育市场成本；新手友好：商品好描述、体积小发货轻、决策快，适合铺量上架 | W39: 常规备选，放在长尾分类；用低价冲量，不单独投流
A40: 38 | B40: 洗衣杯 | C40: B | D40: 6.2 | E40: 53 | F40: 30 | G40: ¥25–36 | H40: 24 | I40: 39 | J40: 65 | K40: 2.5 | L40: 30 | M40: 0.5 | N40: 2.2 | O40: 8 | P40: 6.7 | Q40: 6 | R40: 10 | S40: 9 | T40: 6 | U40: =COUNTIF(SKU明细!D3:D607,B40) -> 1 | V40: 需求中等：「想要」人数中位数 2、有想要标签的在售占比 12/30，属于有搜索但竞争平缓的常规位；单件利润空间可观：全新竞品中位价 ¥53，P25–P75 主流带 ¥39–65，有腾挪定价空间；竞争中等：Top30 中出现 1 个不同品牌，需要在主图和标题上做出差异；售后可控：常规小家电，做好成色描述与功能实测视频即可；⚠️ 合规强监管：属强资质敏感品类，资质/标签/宣称任一不合规即触发下架或扣分；有一定复购：刀头/磨头/袋装等配套件可带动二次成交；自有品牌在该品类已有零星在售（2 条，占 7%），说明存在成交但尚未形成压倒性优势，适合抢占头部位置；新手友好：商品好描述、体积小发货轻、决策快，适合铺量上架 | W40: 常规备选，放在长尾分类；用低价冲量，不单独投流
...

Sheet SKU明细
A1: SKU 级选品清单（按评级与评分排序；建议售价=单件挂价起点，最低可接受价=含运费不亏的保本红线）
A2: 序号 | B2: 品牌 | C2: 评级 | D2: 品类 | E2: 产品名称 | F2: 商品名称 | G2: 商品编码 | H2: 建议售价 | I2: 建议区间 | J2: 最低可接受价 | K2: 竞品中位价 | L2: 想要中位 | M2: 综合评分 | N2: 行动建议
A3: 1 | B3: mericle | C3: S | D3: 剃须刀刀头 | E3: 刀头 | F3: 剃须刀/刀头（塑封） | G3: TXD-04 | H3: 12 | I3: ¥9–15 | J3: 8 | K3: 15 | L3: 113 | M3: 8.17 | N3: 全员力推，首批打满库存；标题带「全新未拆封+实拍」，主图放品牌背书
A4: 2 | B4: mericle | C4: S | D4: 剃须刀刀头 | E4: mericle便携式剃须刀/刀头 | F4: M/迷你剃须刀/二代/刀头 | G4: TXD-38 | H4: 12 | I4: ¥9–15 | J4: 8 | K4: 15 | L4: 113 | M4: 8.17 | N4: 全员力推，首批打满库存；标题带「全新未拆封+实拍」，主图放品牌背书
A5: 3 | B5: mericle | C5: S | D5: 剃须刀刀头 | E5: mericle鼻毛修剪器刀头 | F5: 美丽蔻BMXJQ 刀头 | G5: Mericle-bmxjq001 | H5: 12 | I5: ¥9–15 | J5: 8 | K5: 15 | L5: 113 | M5: 8.17 | N5: 全员力推，首批打满库存；标题带「全新未拆封+实拍」，主图放品牌背书
A6: 4 | B6: mericle | C6: S | D6: 剃须刀刀头 | E6: mericle鼻毛修剪器刀头 | F6: Mericle/BMXJQ/黑色/刀头 | G6: Mericle/BMXJQ/DT | H6: 12 | I6: ¥9–15 | J6: 8 | K6: 15 | L6: 113 | M6: 8.17 | N6: 全员力推，首批打满库存；标题带「全新未拆封+实拍」，主图放品牌背书
A7: 5 | B7: mericle | C7: S | D7: 剃须刀刀头 | E7: mericle鼻毛修剪器刀头 | F7: Mericle/BMXJQ/二代刀头 | G7: Mericle/BMXJQ/002 | H7: 12 | I7: ¥9–15 | J7: 8 | K7: 15 | L7: 113 | M7: 8.17 | N7: 全员力推，首批打满库存；标题带「全新未拆封+实拍」，主图放品牌背书
A8: 6 | B8: mericle | C8: S | D8: 剃须刀刀头 | E8: 康佳鼻毛修剪器刀头 | F8: 康佳/BMXJQ/二代/刀头 | G8: BMXJQ-07 | H8: 12 | I8: ¥9–15 | J8: 8 | K8: 15 | L8: 113 | M8: 8.17 | N8: 全员力推，首批打满库存；标题带「全新未拆封+实拍」，主图放品牌背书
A9: 7 | B9: mericle | C9: S | D9: 剃须刀刀头 | E9: mericle鼻毛修剪器刀头 | F9: M/BMXJQ/五代/刀头 | G9: BMXJQ-16 | H9: 12 | I9: ¥9–15 | J9: 8 | K9: 15 | L9: 113 | M9: 8.17 | N9: 全员力推，首批打满库存；标题带「全新未拆封+实拍」，主图放品牌背书
A10: 8 | B10: mericle | C10: S | D10: 剃须刀刀头 | E10: 剃须刀刀头 | F10: Mericle/透明双头剃须刀/刀头 | G10: TXD-92 | H10: 12 | I10: ¥9–15 | J10: 8 | K10: 15 | L10: 113 | M10: 8.17 | N10: 全员力推，首批打满库存；标题带「全新未拆封+实拍」，主图放品牌背书
A11: 9 | B11: mericle | C11: S | D11: 剃须刀刀头 | E11: 刀头 | F11: 多功能剃须刀YC-808/刀头 | G11: TXD-138 | H11: 12 | I11: ¥9–15 | J11: 8 | K11: 15 | L11: 113 | M11: 8.17 | N11: 全员力推，首批打满库存；标题带「全新未拆封+实拍」，主图放品牌背书
A12: 10 | B12: mericle | C12: S | D12: 剃须刀刀头 | E12: 毛球修剪器刀头 | F12: Mericle/毛球修剪器01/刀头 | G12: MQXJQ-11 | H12: 12 | I12: ¥9–15 | J12: 8 | K12: 15 | L12: 113 | M12: 8.17 | N12: 全员力推，首批打满库存；标题带「全新未拆封+实拍」，主图放品牌背书
A13: 11 | B13: mericle | C13: S | D13: 剃须刀刀头 | E13: 手动刮胡刀刀头 | F13: Mericle/手动剃须刀/MSD-001/刀头 | G13: TXD-123 | H13: 12 | I13: ¥9–15 | J13: 8 | K13: 15 | L13: 113 | M13: 8.17 | N13: 全员力推，首批打满库存；标题带「全新未拆封+实拍」，主图放品牌背书
A14: 12 | B14: 康佳 | C14: S | D14: 剃须刀刀头 | E14: 康佳便携式剃须刀刀头 | F14: 剃须刀/刀头（塑封） | G14: TXD-04 | H14: 12 | I14: ¥9–15 | J14: 8 | K14: 15 | L14: 113 | M14: 8.17 | N14: 全员力推，首批打满库存；标题带「全新未拆封+实拍」，主图放品牌背书
... A436: 434 | B436: mericle | C436: B | D436: 黑头仪 | E436: 黑头仪 | F436: Mericle/小气泡黑头仪/X19（Z） | G436: Mericle-HTY-03 | H436: 22 | I436: ¥17–27 | J436: 16 | K436: 36 | L436: 2.5 | M436: 5.55 | N436: 常规备选，放在长尾分类；用低价冲量，不单独投流
A437: 435 | B437: mericle | C437: B | D437: 黑头仪 | E437: 黑头仪 | F437: Mericle/小气泡黑头仪/XQP003（新款） | H437: 22 | I437: ¥17–27 | J437: 16 | K437: 36 | L437: 2.5 | M437: 5.55 | N437: 常规备选，放在长尾分类；用低价冲量，不单独投流
A438: 436 | B438: 美悟 | C438: B | D438: 黑头仪 | E438: 美悟微晶吸黑头仪 | F438: 美悟 黑头仪（充电款） 美悟 黑头仪（充电款） | G438: MY-HTC MY-HTD | H438: 22 | I438: ¥17–27 | J438: 16 | K438: 36 | L438: 2.5 | M438: 5.55 | N438: 常规备选，放在长尾分类；用低价冲量，不单独投流
A439: 437 | B439: 通货 | C439: B | D439: 洗眼液 | E439: 洗眼液 | F439: 洗眼液/260ml | G439: XYY-01 | H439: 12 | I439: ¥10–13 | J439: 10 | K439: 18 | L439: 18.5 | M439: 5.54 | N439: 常规备选，放在长尾分类；用低价冲量，不单独投流
A440: 438 | B440: mericle | C440: B | D440: 鼻毛修剪器 | E440: mericle鼻毛修剪器 | F440: 美丽蔻BMXJQ充电款 | G440: Mericle-bmxjqC | H440: 12 | I440: ¥10–15 | J440: 10 | K440: 15 | L440: 2 | M440: 5.49 | N440: 常规备选，放在长尾分类；用低价冲量，不单独投流
A441: 439 | B441: mericle | C441: B | D441: 鼻毛修剪器 | E441: mericle鼻毛修剪器 | F441: Mericle/BMXJQ/黑色 | G441: Mericle/BMXJQ/HS | H441: 12 | I441: ¥10–15 | J441: 10 | K441: 15 | L441: 2 | M441: 5.49 | N441: 常规备选，放在长尾分类；用低价冲量，不单独投流
A442: 440 | B442: mericle | C442: B | D442: 鼻毛修剪器 | E442: mericle鼻毛修剪器 | F442: Mericle/BMXJQ/二代 | G442: M/BMXJQ/0310 | H442: 12 | I442: ¥10–15 | J442: 10 | K442: 15 | L442: 2 | M442: 5.49 | N442: 常规备选，放在长尾分类；用低价冲量，不单独投流
A443: 441 | B443: mericle | C443: B | D443: 鼻毛修剪器 | E443: mericle鼻毛修剪器 | F443: Mericle/BMXJQ/三代 | G443: BMXJQ-12 | H443: 12 | I443: ¥10–15 | J443: 10 | K443: 15 | L443: 2 | M443: 5.49 | N443: 常规备选，放在长尾分类；用低价冲量，不单独投流
A444: 442 | B444: mericle | C444: B | D444: 鼻毛修剪器 | E444: mericle鼻毛修剪器 | F444: M/BMXJQ/五代/橙色/BMQ-003 | G444: BMXJQ-14 | H444: 12 | I444: ¥10–15 | J444: 10 | K444: 15 | L444: 2 | M444: 5.49 | N444: 常规备选，放在长尾分类；用低价冲量，不单独投流
A445: 443 | B445: mericle | C445: B | D445: 鼻毛修剪器 | E445: mericle鼻毛修剪器 | F445: M/BMXJQ/五代/蓝色/BMQ-003 | G445: BMXJQ-15 | H445: 12 | I445: ¥10–15 | J445: 10 | K445: 15 | L445: 2 | M445: 5.49 | N445: 常规备选，放在长尾分类；用低价冲量，不单独投流
A446: 444 | B446: mericle | C446: B | D446: 鼻毛修剪器 | E446: mericle鼻毛修剪器 | F446: M/BMXJQ/五代/黑色/BMQ-003 | G446: BMXJQ-42 | H446: 12 | I446: ¥10–15 | J446: 10 | K446: 15 | L446: 2 | M446: 5.49 | N446: 常规备选，放在长尾分类；用低价冲量，不单独投流
A447: 445 | B447: mericle | C447: B | D447: 鼻毛修剪器 | E447: mericle鼻毛修剪器 | F447: Mericle/BMXJQ/七代/蓝色 | G447: BMXJQ-21 | H447: 12 | I447: ¥10–15 | J447: 10 | K447: 15 | L447: 2 | M447: 5.49 | N447: 常规备选，放在长尾分类；用低价冲量，不单独投流
A448: 446 | B448: mericle | C448: B | D448: 鼻毛修剪器 | E448: mericle鼻毛修剪器 | F448: Mericle/BMXJQ/七代/黑色 | G448: BMXJQ-22 | H448: 12 | I448: ¥10–15 | J448: 10 | K448: 15 | L448: 2 | M448: 5.49 | N448: 常规备选，放在长尾分类；用低价冲量，不单独投流
A449: 447 | B449: mericle | C449: B | D449: 鼻毛修剪器 | E449: 鼻毛修剪器 | F449: Mericle /电动BMXJQ升级款/蓝色 | G449: BMXJQ-35 | H449: 12 | I449: ¥10–15 | J449: 10 | K449: 15 | L449: 2 | M449: 5.49 | N449: 常规备选，放在长尾分类；用低价冲量，不单独投流
... A607: 605 | B607: 康佳 | C607: D | D607: 配件周边 | E607: / | F607: 透明罐 | G607: TMG-01 | H607: 20 | I607: ¥16–23 | J607: 15 | K607: 37 | L607: 13 | M607: 6.85 | N607: 不建议投入：合规/售后/需求三重风险，优先出库存或转做搭售赠品

Sheet 品牌品类矩阵
A1: 品牌 × 品类供给矩阵（数字=该品牌该品类 SKU 数，空白=无货，可作差异化选品方向）
A2: 品类 | B2: 评级 | C2: mericle | D2: 夏新 | E2: 奥克斯 | F2: 康佳 | G2: 现代 | H2: 美悟 | I2: 通货 | J2: 合计 | K2: 建议售价
A3: 便携迷你剃须刀 | B3: B | C3: 20 | D3: 23 | E3: 2 | F3: 45 | G3: 1 | H3: 0 | I3: 0 | J3: =SUM(C3:I3) -> 91
A4: 鼻毛修剪器 | B4: B | C4: 15 | D4: 1 | E4: 0 | F4: 23 | G4: 3 | H4: 1 | I4: 0 | J4: =SUM(C4:I4) -> 43
A5: 电动剃须刀 | B5: B | C5: 15 | D5: 4 | E5: 0 | F5: 7 | G5: 0 | H5: 2 | I5: 3 | J5: =SUM(C5:I5) -> 31
A6: 电动剃毛器 | B6: C | C6: 15 | D6: 0 | E6: 0 | F6: 13 | G6: 0 | H6: 0 | I6: 0 | J6: =SUM(C6:I6) -> 28
A7: 理发器 | B7: B | C7: 3 | D7: 0 | E7: 0 | F7: 21 | G7: 0 | H7: 0 | I7: 2 | J7: =SUM(C7:I7) -> 26
A8: 电动磨脚器 | B8: B | C8: 10 | D8: 3 | E8: 0 | F8: 8 | G8: 0 | H8: 3 | I8: 1 | J8: =SUM(C8:I8) -> 25
A9: 直发梳 | B9: B | C9: 15 | D9: 0 | E9: 0 | F9: 8 | G9: 0 | H9: 1 | I9: 1 | J9: =SUM(C9:I9) -> 25
A10: 剃须刀刀头 | B10: S | C10: 11 | D10: 3 | E10: 0 | F10: 8 | G10: 1 | H10: 0 | I10: 0 | J10: =SUM(C10:I10) -> 23
A11: 矫姿带 | B11: C | C11: 19 | D11: 0 | E11: 0 | F11: 0 | G11: 0 | H11: 0 | I11: 0 | J11: =SUM(C11:I11) -> 19
A12: 电动牙刷 | B12: B | C12: 1 | D12: 0 | E12: 0 | F12: 7 | G12: 0 | H12: 7 | I12: 0 | J12: =SUM(C12:I12) -> 15
A13: 电动睫毛卷 | B13: B | C13: 9 | D13: 0 | E13: 0 | F13: 0 | G13: 0 | H13: 5 | I13: 0 | J13: =SUM(C13:I13) -> 14
A14: 车载吸尘器 | B14: B | C14: 11 | D14: 0 | E14: 0 | F14: 0 | G14: 1 | H14: 2 | I14: 0 | J14: =SUM(C14:I14) -> 14
... A94: 隐形眼镜清洁盒 | B94: B | C94: 1 | D94: 0 | E94: 0 | F94: 0 | G94: 0 | H94: 0 | I94: 0 | J94: =SUM(C94:I94) -> 1
A95: 合计 | C95: =SUM(C3:C94) -> 279 | D95: =SUM(D3:D94) -> 64 | E95: =SUM(E3:E94) -> 2 | F95: =SUM(F3:F94) -> 162 | G95: =SUM(G3:G94) -> 19 | H95: =SUM(H3:H94) -> 42 | I95: =SUM(I3:I94) -> 37 | J95: =SUM(J3:J94) -> 605

Sheet 定价与上架策略
A1: 定价与上架策略手册
A3: 一、定价原则
A4: 竞品锚定 | B4: 建议售价基于闲鱼在售竞品价格分位测算；优先取「全新未拆封」子集的中位价（本表货源为全新货），避开二手折价干扰。
A5: 分位取值 | B5: S/A 级取 P25–P50 主流走量带；B/C 级取 P10–P25 低价冲量带；D 级仅求快速回笼资金。
A6: 保本红线 | B6: 最低可接受价 = P10 × 0.95。低于此价上架即亏，需核对进货成本后决定是否放弃。
A7: 成本核算 | B7: 净利 = 建议售价 − 进货成本 − 运费 − 平台费。净利低于 ¥8 的 SKU 建议直接放弃。
A8: 通货提示 | B8: 本表多为通货/白牌，定价务必低于同款品牌旗舰；用「批量清仓/尾货/公司福利」解释低价，转化率明显更高。
A10: 二、标题与主图
A11: 标题公式 | B11: 品牌 + 品类 + 核心参数 + 「全新未拆封」+ 「实拍」。例：康佳 便携式剃须刀 双刀头防水Type-C充电 全新未拆封 实拍
A12: 主图三张 | B12: ①实物实拍（非官方图）②开箱/功能演示 ③尺寸对比图
A13: 搜索词 | B13: 标题覆盖用户真实搜索词：品类词 + 属性词（便携/防水/无线/迷你）+ 场景词（学生/差旅/送礼）。
A15: 三、上架与售后风控
A16: 电器必拍 | B16: 电器类上架前拍 15 秒开箱视频存档，可大幅降低退货纠纷与「描述不符」投诉。
A17: 成色描述 | B17: 如实写明功能状态、有无划痕、是否拆封；低价商品尤其要写清「为什么低价」。
A18: 耗材组合 | B18: 刀头/磨头/袋装/口罩等耗材单独建合集链接，与主机打包做「主品+耗材」组合价，锁定复购。
A19: 合规红线 | B19: 洗眼液/明目护眼液/漱口水/芦荟胶/强脉冲光/脱毛仪等强监管品类，个人商家不建议上架；标题禁用「治疗/根治/祛斑/杀菌」等词。
A21: 四、节奏建议
A22: 首批上架 | B22: 先上 S+A 级品类全部 SKU（建议 30–60 个链接），跑通自然流量后再扩。
A23: 测款节奏 | B23: 上架后 7 天内出单即补货并加投；满 14 天零出单则降价一档或下架换品。
A24: 季节备货 | B24: 夏季备风扇/挂腰风扇/防晒口罩/驱蚊手环；冬季备毛球修剪器/烘鞋器/保暖口罩/暖菜板；春季备修足器/除螨仪。
A25: 复购运营 | B25: 耗材类主品成交后 15 天内推送耗材复购提醒，耗材毛利率通常高于主品。
